Workbook
Name BRANDS: Diverse!$J$4:$J$40
Name COUNTRIES: Diverse!$R$3:$R$235
Name CURRENCY: Diverse!$X$4:$X$168
Name DAYS: Diverse!$G$3:$G$34
Name DAYSTRS: Diverse!$G$45:$G$75
Name GRADINGS: Diverse!$U$3:$U$43
Name HOUSINGLAY: Diverse!$N$3:$N$10
Name HOUSINGREARING: Diverse!$N$17:$N$19
Name Languages: Diverse!$AC$4:$AC$19
Name MONTH: Diverse!$D$3:$D$15
Name MONTHTRS: Diverse!$D$44:$D$56
Name YEAR: Diverse!$B$3:$B$16
Name YEARTRS: Diverse!$B$45:$B$57

Sheet Std
A1: Breed | B1: ISA BROWN Baiada ALT 2021
B2: L | C2: O | D2: H | E2: AG | F2: X | G2: V | H2: I | I2: J | J2: C | K2: D | L2: B | M2: K
A3: Age | B3: %lay HD | C3: AEW | D3: BW | E3: Daily egg mass | F3: Cumulative egg mass HH | G3: Eggs HH | H3: Average of BW MIN | I3: Average of BW MAX | J3: Feed min | K3: Feed max | L3: Feed avg | M3: Liveability rearing
A4: 1 | B4: 0 | C4: 0 | D4: 65.5 | E4: 0 | F4: 0 | G4: 0 | H4: 63.8625 | I4: 67.1375 | J4: 10 | K4: 12 | L4: 11 | M4: 99.7
A5: 2 | B5: 0 | C5: 0 | D5: 117.5 | E5: 0 | F5: 0 | G5: 0 | H5: 114.5625 | I5: 120.4375 | J5: 17.224768 | K5: 19.224768 | L5: 18.224768 | M5: 99.45
A6: 3 | B6: 0 | C6: 0 | D6: 191.5 | E6: 0 | F6: 0 | G6: 0 | H6: 186.7125 | I6: 196.2875 | J6: 24.165692 | K6: 26.165692 | L6: 25.165692 | M6: 99.25
A7: 4 | B7: 0 | C7: 0 | D7: 275.5 | E7: 0 | F7: 0 | G7: 0 | H7: 268.6125 | I7: 282.3875 | J7: 30.387181 | K7: 32.387181 | L7: 31.387181 | M7: 99.1
A8: 5 | B8: 0 | C8: 0 | D8: 370 | E8: 0 | F8: 0 | G8: 0 | H8: 360.75 | I8: 379.25 | J8: 35.969504 | K8: 37.969504 | L8: 36.969504 | M8: 98.95
A9: 6 | B9: 0 | C9: 0 | D9: 471 | E9: 0 | F9: 0 | G9: 0 | H9: 459.225 | I9: 482.775 | J9: 40.99015 | K9: 42.99015 | L9: 41.99015 | M9: 98.8
A10: 7 | B10: 0 | C10: 0 | D10: 577.5 | E10: 0 | F10: 0 | G10: 0 | H10: 563.0625 | I10: 591.9375 | J10: 45.523827 | K10: 47.523827 | L10: 46.523827 | M10: 98.65
A11: 8 | B11: 0 | C11: 0 | D11: 686.5 | E11: 0 | F11: 0 | G11: 0 | H11: 669.3375 | I11: 703.6625 | J11: 49.64246 | K11: 51.64246 | L11: 50.64246 | M11: 98.55
A12: 9 | B12: 0 | C12: 0 | D12: 793.5 | E12: 0 | F12: 0 | G12: 0 | H12: 773.6625 | I12: 813.3375 | J12: 53.415196 | K12: 55.415196 | L12: 54.415196 | M12: 98.45
A13: 10 | B13: 0 | C13: 0 | D13: 894.5 | E13: 0 | F13: 0 | G13: 0 | H13: 872.1375 | I13: 916.8625 | J13: 56.908399 | K13: 58.908399 | L13: 57.908399 | M13: 98.35
A14: 11 | B14: 0 | C14: 0 | D14: 989 | E14: 0 | F14: 0 | G14: 0 | H14: 964.275 | I14: 1013.725 | J14: 60.185653 | K14: 62.185653 | L14: 61.185653 | M14: 98.25
A15: 12 | B15: 0 | C15: 0 | D15: 1076.5 | E15: 0 | F15: 0 | G15: 0 | H15: 1049.5875 | I15: 1103.4125 | J15: 63.307761 | K15: 65.307761 | L15: 64.307761 | M15: 98.15
... A113: 110 | B113: 0 | C113: 0 | D113: 0 | E113: 0 | F113: 29.019946 | G113: 460.13022 | H113: 0 | I113: 0 | J113: -1 | K113: 1 | L113: 0 | M113: 0

Sheet Language
B1: ='General Input'!B12 -> English
A2: WS1 | B2: =VLOOKUP(Languages!B2,Languages!$B$2:$S$400,MATCH($B$1,Languages!$B$1:$S$1,0),FALSE) -> General input
B3: =VLOOKUP(Languages!B3,Languages!$B$2:$S$400,MATCH($B$1,Languages!$B$1:$S$1,0),FALSE) -> Spread sheet explanation
B4: =VLOOKUP(Languages!B4,Languages!$B$2:$S$400,MATCH($B$1,Languages!$B$1:$S$1,0),FALSE) -> 0
B5: =VLOOKUP(Languages!B5,Languages!$B$2:$S$400,MATCH($B$1,Languages!$B$1:$S$1,0),FALSE) -> Please fill in the coloured cells.
B6: =VLOOKUP(Languages!B6,Languages!$B$2:$S$400,MATCH($B$1,Languages!$B$1:$S$1,0),FALSE) -> Your document name will be in cell B25
B7: =VLOOKUP(Languages!B7,Languages!$B$2:$S$400,MATCH($B$1,Languages!$B$1:$S$1,0),FALSE) -> You can use this format to name your document.
B8: =VLOOKUP(Languages!B8,Languages!$B$2:$S$400,MATCH($B$1,Languages!$B$1:$S$1,0),FALSE) -> Required informations
B9: =VLOOKUP(Languages!B9,Languages!$B$2:$S$400,MATCH($B$1,Languages!$B$1:$S$1,0),FALSE) -> Every calculation and graph will generate themselves from the data
B10: =VLOOKUP(Languages!B10,Languages!$B$2:$S$400,MATCH($B$1,Languages!$B$1:$S$1,0),FALSE) -> entered in "input general", "input rearing" and "input laying" worksheets.
B11: =VLOOKUP(Languages!B11,Languages!$B$2:$S$400,MATCH($B$1,Languages!$B$1:$S$1,0),FALSE) -> Hatch date
B12: =VLOOKUP(Languages!B12,Languages!$B$2:$S$400,MATCH($B$1,Languages!$B$1:$S$1,0),FALSE) -> Breed
B13: =VLOOKUP(Languages!B13,Languages!$B$2:$S$400,MATCH($B$1,Languages!$B$1:$S$1,0),FALSE) -> Housing system during laying period
B14: =VLOOKUP(Languages!B14,Languages!$B$2:$S$400,MATCH($B$1,Languages!$B$1:$S$1,0),FALSE) -> Company name / Egg Organisation
... B60: =VLOOKUP(Languages!B60,Languages!$B$2:$S$400,MATCH($B$1,Languages!$B$1:$S$1,0),FALSE) -> Version:
A61: WS2 | B61: =VLOOKUP(Languages!B61,Languages!$B$2:$S$400,MATCH($B$1,Languages!$B$1:$S$1,0),FALSE) -> Rearing input
B62: =VLOOKUP(Languages!B62,Languages!$B$2:$S$400,MATCH($B$1,Languages!$B$1:$S$1,0),FALSE) -> Date
B63: =VLOOKUP(Languages!B63,Languages!$B$2:$S$400,MATCH($B$1,Languages!$B$1:$S$1,0),FALSE) -> Age
B64: =VLOOKUP(Languages!B64,Languages!$B$2:$S$400,MATCH($B$1,Languages!$B$1:$S$1,0),FALSE) -> Mortality
B65: =VLOOKUP(Languages!B65,Languages!$B$2:$S$400,MATCH($B$1,Languages!$B$1:$S$1,0),FALSE) -> Daily
B66: =VLOOKUP(Languages!B66,Languages!$B$2:$S$400,MATCH($B$1,Languages!$B$1:$S$1,0),FALSE) -> Weekly
B67: =VLOOKUP(Languages!B67,Languages!$B$2:$S$400,MATCH($B$1,Languages!$B$1:$S$1,0),FALSE) -> Cum.
B68: =VLOOKUP(Languages!B68,Languages!$B$2:$S$400,MATCH($B$1,Languages!$B$1:$S$1,0),FALSE) -> Transfer
B69: =VLOOKUP(Languages!B69,Languages!$B$2:$S$400,MATCH($B$1,Languages!$B$1:$S$1,0),FALSE) -> Mortality %
B70: =VLOOKUP(Languages!B70,Languages!$B$2:$S$400,MATCH($B$1,Languages!$B$1:$S$1,0),FALSE) -> Number of birds end of period
B71: =VLOOKUP(Languages!B71,Languages!$B$2:$S$400,MATCH($B$1,Languages!$B$1:$S$1,0),FALSE) -> Body weight
B72: =VLOOKUP(Languages!B72,Languages!$B$2:$S$400,MATCH($B$1,Languages!$B$1:$S$1,0),FALSE) -> Actual (g)
B73: =VLOOKUP(Languages!B73,Languages!$B$2:$S$400,MATCH($B$1,Languages!$B$1:$S$1,0),FALSE) -> Unif. %
... B99: =VLOOKUP(Languages!B99,Languages!$B$2:$S$400,MATCH($B$1,Languages!$B$1:$S$1,0),FALSE) -> Water/feed ratio
A100: WS3 | B100: =VLOOKUP(Languages!B100,Languages!$B$2:$S$400,MATCH($B$1,Languages!$B$1:$S$1,0),FALSE) -> Laying input
B101: =VLOOKUP(Languages!B101,Languages!$B$2:$S$400,MATCH($B$1,Languages!$B$1:$S$1,0),FALSE) -> Farm name:
B102: =VLOOKUP(Languages!B102,Languages!$B$2:$S$400,MATCH($B$1,Languages!$B$1:$S$1,0),FALSE) -> House no. :
B103: =VLOOKUP(Languages!B103,Languages!$B$2:$S$400,MATCH($B$1,Languages!$B$1:$S$1,0),FALSE) -> Hatch date:
B104: =VLOOKUP(Languages!B104,Languages!$B$2:$S$400,MATCH($B$1,Languages!$B$1:$S$1,0),FALSE) -> Date at 18 weeks old :
B105: =VLOOKUP(Languages!B105,Languages!$B$2:$S$400,MATCH($B$1,Languages!$B$1:$S$1,0),FALSE) -> Transfer date:
B106: =VLOOKUP(Languages!B106,Languages!$B$2:$S$400,MATCH($B$1,Languages!$B$1:$S$1,0),FALSE) -> Number of laying birds housed:
B107: =VLOOKUP(Languages!B107,Languages!$B$2:$S$400,MATCH($B$1,Languages!$B$1:$S$1,0),FALSE) -> 0
B108: =VLOOKUP(Languages!B108,Languages!$B$2:$S$400,MATCH($B$1,Languages!$B$1:$S$1,0),FALSE) -> Date beginning of the week
B109: =VLOOKUP(Languages!B109,Languages!$B$2:$S$400,MATCH($B$1,Languages!$B$1:$S$1,0),FALSE) -> Age in weeks
B110: =VLOOKUP(Languages!B110,Languages!$B$2:$S$400,MATCH($B$1,Languages!$B$1:$S$1,0),FALSE) -> No. of birds end of week
...

Sheet Languages
B1: 1 | C1: Deutsch | D1: English | E1: Español | F1: Français | G1: Indonesia | H1: Italiano | I1: Nederland | J1: Polski | K1: Português | L1: Slovenský | M1: South Slavic | N1: русский | O1: العربية | P1: 한국의 | Q1: 中国 | R1: 日本の
A2: WS1 | B2: 2 | C2: Haupteingabe | D2: General input | E2: Datos generales | F2: Informations générales | G2: Input umum | H2: Informazioni Generali | I2: Invoer | J2: Dane ogólne I informacje | K2: Entrada geral | L2: Všeobecné vstupné údaje | M2: Generalni unos podataka | N2: Общие данные | O2: بيانات عامة | P2: 일반 | Q2: 一般数据输入 | R2: 一般情報入力
B3: 3 | C3: Arbeitsanweisung | D3: Spread sheet explanation | E3: Explicación de la hoja de cálculo | F3: Explications sur le fichier | G3: Lembar penjelasan | H3: Spiegazione Foglio Di Calcolo | I3: Uitleg excel document | J3: Wyjaśnienia | K3: Explicação do programa | L3: Vysvetlenie | M3: Objašnjenje tabele | N3: Объяснение | O3: شرح لجدول البيانات | P3: 스프레드시트설명 | Q3: 填表说明 | R3: エクセルシートの説明
B4: 4
B5: 5 | C5: Bitte die farbigen Cellen auffüllen | D5: Please fill in the coloured cells. | E5: Por favor, rellene las celdas coloreadas | F5: Merci de remplir les cellules colorées | G5: Silahkan mengisi di sel yang diwarnai | H5: Prego Completare Le Celle Colorate | I5: Gelieve de gekleurde cellen in te voeren | J5: Należy wypełnić komórki z kolorowym tłem | K5: Por favor preencher as células coloridas | L5: Vyplňte prosím farebné bunky | M5: Molim Vas unesite označena polja | N5: Заполните закрашенные клетки | O5: يرجى ملأ الخلايا الملونة | P5: 색칠된 셀에 기입 | Q5: 请将数字填入蓝色空格. | R5: 色のついたセルのみに入力してください。
B6: 6 | C6: Ihr Dokumentenname wird in Celle B27 | D6: Your document name will be in cell B25 | E6: El nombre del documento aparecerá en la celda B27 | F6: Vous trouverez le nom du fichier en cellule B27 | G6: Nama dokumen Anda akan berada di sel B25 | H6: Nome Vostro Documento Nella Cella B25 | I6: Uw documentnaam staat in cel B27 | J6: Nazwa dokumentu będzie znajdować się w komórce B25 | K6: O nome do documento será na célula B27 | L6: Názov vašej tabuľky bude v bunke B27 | M6: Naziv dokumenta će biti u polju B25 | N6: Название документа в клетке B25 | O6: إسم سجلك سيكون في الخلية رقم ب27 | P6: 문서명은 셀B25에 표시됨 | Q6: 文件名在表格B27 | R6: このドキュメントの名前はセルB25に記入してください。
B7: 7 | C7: Sie können dieses Fromat sur Benennung des Dokumentes | D7: You can use this format to name your document. | E7: Puede usar este formato como nombre para su documento. | F7: Vous pouvez utiliser ce nom afin de sauvegarder votre fichier. | G7: Anda dapat menggunakan format ini untuk memberi nama dokumen anda. | H7: Usare Questo Formato Per Nominare Il Vostro Documento | I7: U kunt dit format gebruiken als documentnaam | J7: Można wykorzystać ten format dla określenia nazwy dokumentu | K7: Você pode usar este formato para nomear seu documento | L7: Pre názov Vášho dokumentu môžete použiť tento formát | M7: Možete koristiti ovaj format za naziv dokumenta | N7: Вы можете дать собственное название этому документу | O7: يمكنك إستعمال هذا النموذج لتسمية سجلك | P7: 이 형식을 문서제목에 사용가능함 | Q7: 可以此格式命名文件 | R7: このフォーマット名は自由に変更できます。
B8: 8 | C8: benötigte Information | D8: Required informations | E8: Informaciones necesarias | F8: Informations requises. | G8: Informasi yang dibutuhkan | H8: Informazioni Richieste | I8: Vereiste informatie | J8: Pole z wymaganym wpisem | K8: Informações necessárias | L8: Požadované informácie | M8: Potrebne informacije | N8: Необходимая информация | O8: المعلومات المطلوبة | P8: 필수정보 | Q8: 所需信息/数据 | R8: 一般情報入力
B9: 9 | C9: Die Berechnungen für die Graphen werden automatisch erstellt. | D9: Every calculation and graph will generate themselves from the data | E9: Los cálculos y gráficos se generarán automáticamente a partir de los datos | F9: Chaque calcul et graphique se générera à partir des données saisies | G9: Setiap perhitungan dan grafik akan dihasilkan dari data | H9: Ogni Calcolo E Grafico Sarà Generato Dai Dati | I9: Grafieken en gecalculeerde data worden automatisch gegenereerd uit uw invoer | J9: Wszystkie wykresy i obliczenia będą wygenerowane automatycznie | K9: Todos os cálculos e gráficos serão gerados a partir dos dados inseridos | L9: Všetky kalkulácie a grafy sa automaticky vygenerujú z údajov | M9: Svaka kalkulacija i grafikon će se generisati sam od podataka | N9: Указанные данные будут посчитаны и отражены на графике | O9: كل عملية حسابية ورسم بياني ينتج نفسه من المعلومات | P9: 모든 계산 및 그래프는 데이터로부터 생성합니다 | Q9: 计算结果和曲线将自动生成 | R9: 入力データより、性能値とグラフは自動的に作られます。
B10: 10 | C10: In folgende Arbeitsblätter muss eingetragen werden: Eingabe Allgemein, Eingabe Aufzucht, Eingabe Lege | D10: entered in "input general", "input rearing" and "input laying" worksheets. | E10: introducidos en las hojas "datos generales", "datos de recría" y "datos de puesta". | F10: dans les feuilles "Informations générales", "Données d'élevage" et "Données de ponte" | G10: Masukan dalam lembar kerja "input umum", "input growing" dan "input laying". | H10: Inseriti In Foglio Lavoro"Info Generali","Info Svezzamento" E "Info Deposizione" | I10: in de tabbladen "input general", "input rearing" en "input laying". | J10: Proszę wprowadzić "dane podstawowe", "dane odchowu" i "dane produkcyjne" | K10: Entrada na planilha "Dados Gerais", "Dados de cria" e "Dados de postura" | L10: ktoré vložíte do listov "Všeobecné vstupné údaje", "Obdobie odchovu" a "Obdobie produkcie" | M10: uneto u tabele ‚‚ generalni unos‚‚ , ‚‚unos za odgoj‚, i ‚‚unos za proizvodnju‚‚ | N10: Обратите внимание на вкладки "общие данные", "данные по выращиванию" и "данные по кладке". | P10: "일반입력", "육성입력", "산란입력"을 기입한다. | Q10: 进入"一般数据", "生长期记录" 和 "产蛋期记录"工作表. | R10: 「一般情報入力」, 「育雛/育成入力」 と 「産卵入力」 ワークシートにデータを入力してください
B11: 11 | C11: Schlupfdatum | D11: Hatch date | E11: Fecha de nacimiento | F11: Date d'éclosion | G11: Tanggal menetas | H11: Data Schiusa | I11: Uitkomstdatum | J11: Data wylęgu | K11: Data de eclosão | L11: Dátum liahnutia | M11: Datum inkubiranja | N11: Дата вывода | O11: تاريخ التفقيس | P11: 부화데이터 | Q11: 出雏日期 | R11: 孵化日
B12: 12 | C12: Zucht/ Genetik | D12: Breed | E12: Estirpe | F12: Souche | G12: Jenis Bibit | H12: Incrocio | I12: Ras/Merk | J12: Linia | K12: Linhagem | L12: Hybrid | M12: Hibrid | N12: Кросс | O12: العرق | P12: 육성 | Q12: 品种 | R12: 鶏種
B13: 13 | C13: Einrichtungssystem durch die Legeperiode | D13: Housing system during laying period | E13: Sistema de alojamiento en producción | F13: Système de production | G13: Sistem kandang selama periode bertelur | H13: Sistema Di Allevamento Durante Lo Svezzamento | I13: Huisvestingssysteem legperiode | J13: system produkcyjny | K13: Sistema de alojamento durante o período de postura | L13: Systém ustajnenia v produkcii | M13: Sistem držanja u periodu nošenja | N13: Система содержания в период кладки | O13: نظام التربية خلال مرحلة إنتاج البيض | P13: 산란기 계사 시스템 | Q13: 产蛋期鸡舍类型 | R13: 産卵期間中の鶏舎構造
B14: 14 | C14: Firmenname, Eierorganisation | D14: Company name / Egg Organisation | E14: Nombre de la compañía | F14: Organisation | G14: Nama Perusahaan/ Organisasi | H14: Nome Azienda/Organizzazione | I14: Bedrijfsnaam | J14: Nazwa firmy/ integracji | K14: Nome da companhia/ Empresa de ovos | L14: Názov firmy/Výrobcu vajec | M14: Naziv kompanije/ Farme | N14: Название компании | O14: إسم الشركة\منظمة البيض | P14: 회사명/계란협회 | Q14: 公司名称/产蛋场名称 | R14: 御社名
B15: 15 | C15: Betriebsname | D15: Laying farm name | E15: Nombre de la granja de puesta | F15: Ferme de production | G15: Nama Farm | H15: Nome Azienda Deposizione | I15: Bedrijfsnaam (2) | J15: Nazwa fermy produkcyjnej | K15: Nome da granja | L15: Názov znáškovej farmy | M15: Naziv farme za eksploataciju | N15: Название фермы | O15: إسم مزرعة إنتاج البيض | P15: 산란농장명 | Q15: 产蛋鸡场名称 | R15: 採卵農場名
B16: 16 | C16: Stallnummer | D16: House No. during laying period | E16: Nº de nave de puesta | F16: Bâtiment n° | G16: Nomor Kandang selama periode produksi | H16: Nr.Del Capannone Durante Il Periodo Di Deposizione | I16: Stalnummer | J16: Nr. kurnika produkcyjnego | K16: Numero do Galpão durante o período de postura | L16: Číslo haly v období produkcie | M16: Broj objekta u periodu nošenja | N16: Номер птичника в течении периода кладки | O16: عنبر رقم. خلال مرحلة إنتاج البيض | P16: 산란기 계사번호 | Q16: 产蛋鸡舍编号 | R16: 産卵鶏舎番号
B17: 17 | C17: Land | D17: Country | E17: País | F17: Pays | G17: Negara | H17: Paese | I17: Land | J17: Kraj | K17: País | L17: Krajina | M17: Zemlja | N17: Страна | O17: البلد | P17: 국가 | Q17: 国家 | R17: 国
B18: 18 | C18: aktuell | D18: Currency | E18: Moneda | F18: Devise | G18: Mata uang | H18: Valuta | I18: Valuta | J18: Waluta | K18: Moeda | L18: Mena | M18: Valuta | N18: Текущие | O18: العملة | P18: 전화 | Q18: 货币名称 | R18: 通貨
B19: 19 | C19: Berater Kontakt | D19: Technical contact (e-mail) | E19: Contacto técnico (e-mail) | F19: Contact technique (e-mail) | G19: Kontak e-mail | H19: Contatto Tecnico(E-Mail) | I19: Technisch adviseur (e-mail) | J19: Osoba kontaktowa (e-mail) | K19: Contato técnico (e-mail) | L19: Kontakt (e-mail) | M19: Tehnički kontakt(email) | N19: Контакты (e-mail) | O19: العنوان الإلكتروني | P19: 기술지원연락처(e-mail) | Q19: 技术支持联系方式(e-mail) | R19: 技術担当者 (e-mail)
B20: 20 | C20: Eingefüllter Name | D20: File name | E20: Nombre del archivo | F20: Nom du fichier | G20: Nama file | H20: Nome Del File | I20: Bestandsnaam | J20: Nazwa pliku | K20: Nome do arquivo | L20: Názov súboru (dokumentu) | M20: Naziv datoteke | N20: Имя файла | O20: إسم الملف | P20: 파일명 | Q20: 文件名 | R20: ファイル名
B21: 21 | C21: Bitte senden sie ihre Ergebnisse zu uns | D21: Please send your results to us by clicking on the following button. | E21: Por favor, envíenos los resultados | F21: Merci de nous envoyez vos résultats. | G21: Silakan kirim hasil anda kepada kami. | H21: Prego Inviare I Risultati | I21: ISA is zeer benieuwd naar uw resultaten | J21: Prosimy o przesłanie informacji do nas | K21: Por favor nos envie os resultados. | L21: Prosím, pošlite nám svoje výsledky | M21: Molim Vas da nam pošaljete rezultate klikom na sledeće sivo dugme | N21: Отправляйте нам свои результаты | O21: يرجى إرسال النتائج إلينا | P21: 다음의 회색 버튼을 클릭하여 결과를 보내 주시기 바랍니다. | Q21: 请将鸡群数据发送给我们. | R21: 情報をISAに送信
B22: 22
B23: 23 | C23: Auswahl Blatt | D23: Available sheets | E23: Hojas disponibles | F23: Feuilles disponibles | G23: Lembar tersedia | H23: Fogli Disponibili | I23: BESCHIKBARE TAB BLADEN | J23: dostępne arkusze | K23: Folhas disponíveis | L23: Dostupné listy | M23: Dostupne tabele | N23: Доступные листы | O23: النسخ المتوفرة | P23: 가능한 시트 | Q23: 各表名称 | R23: ワークシート名
A24: Sheets | B24: 24 | C24: Eingabe Aufzucht | D24: Input rearing | E24: Datos de recría | F24: Données d'élevage | G24: Input growing | H24: Informazioni Svezzamento | I24: Invoer opfokperiode | J24: dane odchowu | K24: Dados de cria | L24: Obdobie odchovu | M24: Unos odgoja | N24: Данные по выращиванию | O24: بيانات النمو | P24: 육성기입력 | Q24: 生长期记录表 | R24: 育雛育成入力
B25: 25 | C25: Aufzuchtgraf | D25: Rearing graph | E25: Gráfico de recría | F25: Courbe d'élevage | G25: Grafik growing | H25: Grafico Svezzamento | I25: Grafieken opfokperiode | J25: wykresu odchowu | K25: Gráfico de crescimento | L25: Odchovný graf | M25: Grafikon odgoja | N25: График выращивания | O25: رسم بيانات النمو | P25: 육성기그래프 | Q25: 生长期曲线表 | R25: 育雛育成グラフ
B26: 26 | C26: Eingabe Lege | D26: Input Laying | E26: Datos de puesta | F26: Données de ponte | G26: Input laying | H26: Informazioni Deposizione | I26: Invoer legperiode | J26: produkcyjne | K26: Dados de postura | L26: Obdobie produkcie | M26: Unos nosivosti | N26: Данные кладки | O26: بيانات الإنتاج | P26: 산란기입력 | Q26: 产蛋期记录表 | R26: 産卵入力
B27: 27 | C27: Legeleistungsgrafik | D27: Laying graph | E27: Gráfico de puesta | F27: Courbe de ponte | G27: Grafik laying | H27: Grafico Deposizione | I27: Grafieken legperiode | J27: wykres produkcji | K27: Gráfico de postura | L27: Graf produkcie | M27: Grafikon nosivosti | N27: График кладки | O27: رسم بيانات الإنتاج | P27: 산란기그래프 | Q27: 产蛋期曲线表 | R27: 産卵グラフ
B28: 28 | C28: Masse- & Verbrauchsgrafik | D28: Mass & cons graph | E28: Gráf. masa de huevo y consumo | F28: Masse et conso | G28: Grafik Egg mass & kons. pakan | H28: Grafico Massa E Consumo | I28: Eimassa en voeropname grafiek | J28: Masa jaj i spożycie paszy | K28: Gráfico de Massa e consumo | L28: Vaječná Hmota & Príjem KZ | M28: Grafikon mase | N28: Масса & график потребления | O28: رسم كتلة البيض & إستهلاك العلف | P28: 에그매스(산란량) 및 사료섭취량 | Q28: 产蛋量和饲料消耗曲线 | R28: 採卵 飼料グラフ
B29: 29 | C29: Futterverwertungsgrafik | D29: FCR graph | E29: Gráfico de IC | F29: Courbe d'indice | G29: Grafik FCR | H29: Grafico Indice Di Conversione | I29: VC grafiek | J29: wykres FCR | K29: Gráfico de C.A. | L29: Konverzia KZ | M29: Grafikon konverzije hrane | N29: График конверсии корма | O29: رسم معدل تحويل العلف | P29: 사료전환율그래프 | Q29: 饲料转化率曲线 | R29: 要求率グラフ
B30: 30 | C30: Grafik für eigene Sortierung | D30: Down grading graph | E30: Gráfico de huevos de segunda | F30: Courbe des déclassés | G30: Grafik non standar | H30: Grafico Sottopeso | I30: Grafiek 2e soort | J30: wykres odpadów | K30: Gráfico de ovos de segunda | L30: Neštandard | M30: Opadajuće gradiranje | N30: График сортировки | O30: رسم بياني للبيض درجة ثانية | P30: 다운등급그래프 | Q30: 次品蛋曲线表 | R30: 格外卵グラフ
B31: 31 | C31: Eiersortierung | D31: Egg grading | E31: Clasificación de los huevos | F31: Calibres | G31: Grading Telur | H31: Peso Uova | I31: Verdeling eigewichten | J31: rozkład klas wagowych | K31: Classificação dos ovos | L31: Hmotnostné triedenie vajec | M31: Klasiranje jaja | N31: Категорийеость яйца | O31: حجم البيض | P31: 계란등급 | Q31: 蛋重分级 | R31: 規格卵グラフ
B32: 32 | C32: Graf. Größenverteilung | D32: Egg grading distribution graph | E32: Gráf. clasific. de huevos | F32: Répartition des calibres en % | G32: Grafik grading telur | H32: Grafico Ripartizione Peso Uova | I32: Graf verdeling eigewichten proc | J32: wykres rozkładu klasowego jaj | K32: Gráf. Classif. Ovos. | L32: Rozdelenie hmot. tried vajec | M32: Distribucija klasa jaja | N32: Сортировка яйца по классификаци | O32: رسم توزيعي لحجم البيض | P32: 계란 등급 분포 그래프 | Q32: 蛋重分布图 | R32: 規格等級付卵グラフ
B33: 33 | C33: Eisortierung kum. | D33: Egg grading cum | E33: Clasific. huevos acum. | F33: Répartition des calibres en qt | G33: Kum. telur grading | H33: Peso Uova Cumulativo | I33: Graf verdeling eigewichten week | J33: rozkład klas narastająco | K33: Classificação de ovos acumulado | L33: Triedenie vajec nápočtom | M33: Kumulativno klasiranje jaja | N33: Прирост яиц по классификациям | O33: حجم البيض التراكمي | P33: 계란등급축적 | Q33: 累计蛋重分级 | R33: 累計規格卵グラフ
B34: 34 | C34: Finanselles Blatt | D34: Financial sheet | E34: Cálculos financieros | F34: Profits | G34: Lembar keuangan | H34: Foglio Finanziario | I34: Financiele data | J34: arkusz finansowy | K34: Ficha Financeira | L34: List finančného zhodnotenia | M34: Finansijska lista | N34: Финансы | O34: كشف مالي | P34: 재정시트 | Q34: 经济效益核算表 | R34: 経済性表
B35: 35 | C35: Produktionsdaten | D35: Production data | E35: Datos de producción | F35: Performances de production | G35: Data produksi | H35: Dati Di Produzione | I35: Productie data | J35: dane produkcyjne | K35: Dados de produção | L35: Produkčné údaje | M35: Proizvodni podaci | N35: Данные продуктивности | O35: بيانات الإنتاج | P35: 생산데이터 | Q35: 生产数据 | R35: 生産性データ
B36: 36 | C36: Summe | D36: Summary | E36: Resumen | F36: Résumé de production | G36: Ringkasan | H36: Sommario | I36: Samenvatting | J36: podsumowanie | K36: Resumo | L36: Sumár | M36: Zbir | N36: Итог | O36: ملخص | P36: 정리 | Q36: 总结 | R36: サマリー
B37: 37
B38: 38 | C38: Aktuell | D38: Content | E38: Contenido | F38: Contenu | G38: Daftar Isi | H38: Contenuto | I38: INHOUD | J38: zawartość | K38: Conteúdo | L38: Obsah | M38: Sadržaj | N38: Содержание | O38: محتويات | P38: 함유량 | Q38: 内容 | R38: 内容
B39: 39 | C39: Tägliche und wöchentliche Moratlität, Körpergewicht, Verbrauch und Lichtprogramm. | D39: Daily and weekly mortality, body weight, consumptions and light programs. | E39: Mortalidad diaria y semanal, peso corporal, consumo y programa de iluminación. | F39: Mortalité journalière et hebdomadaire, Poids corporel, consommation et programmes lumineux. | G39: Kematian harian dan mingguan, berat badan, konsumsi dan program pencahayaan. | H39: Mortalita' Giornaliera E Sett.Le,Peso Corporeo,Consumo E Programma Luce | I39: dagelijkse en wekelijkse uitval, lichaamsgewichten, voederopname en lichtprogramma's | J39: Upadki dzienne i tygodniowe, masa ciała, spożycie paszy i program świetlny | K39: Mortalidade diária e semanal, peso corporal, consumo e programa de luz | L39: Denný, týždenný úhyn, ŽH, príjem KZ, svetelný režim | M39: Dnevno i nedeljno uginuće, telesne težine, potrošnje hrane i svetlosni program | N39: Недельный и месячный отход, живая масса, потребление и программа освещения. | O39: الوفيات اليومية و الأسبوعية, وزن الجسم,الإستهلاك العلفي و برامج الإضاءة | P39: 일간/주간 폐사율, 체중, 소비량과 점등프로그램 | Q39: 每天及每周的死亡鸡数、体重、采食量和光照时数。 | R39: 日々と週間の斃死状況、体重、飼料摂取量、光線管理プログラム
B40: 40 | C40: Mortalität, Futterverbrauch, Körpergewicht und Uniformität | D40: Mortality, feed consumption, body weight and uniformity | E40: Mortalidad, consumo de pienso, peso corporal y uniformidad | F40: Mortalité, consommation d'aliment, Poids corporel et homogénéité. | G40: Kematian, konsumsi pakan, berat badan dan keseragaman | H40: Mortalita',Consumo Mangime,Peso Corporeo E Uniformita' | I40: uitval, voeropname, lichaamsgewichten en uniformiteit | J40: upadki, spożycie paszy, masa ciała i wyrównanie | K40: Mortalidade, consumo de alimento, peso corporal e uniformidade | L40: Úhyn, príjem KZ, ŽH, uniformita | M40: Uginuće, potrošnja hrane, telesna težina i ujednačenost | N40: Падеж, потребление корма, живая масса и однородность | O40: الوفيات,استهلاك العلف, وزن الجسم ومعدل التجانس | P40: 폐사율 사료 소비량, 체중 및 균일도 | Q40: 死亡鸡数、采食量、体重和均匀度。 | R40: 斃死、飼料摂取、体重、均一性
...

Sheet Graph values
B4: =Language!B258 -> Liveability | C4: =Language!B259 -> Weekly mortality % | D4: =Language!B260 -> Laying % | E4: =Language!B261 -> Laying rate std. | F4: =Language!B262 -> Egg Weight | G4: =Language!B263 -> Egg weight std. | H4: =Language!B264 -> Body weight | J4: =Language!B265 -> Laying body weight std. | K4: =Language!B266 -> Cons | L4: =Language!B267 -> Egg mass | M4: =Language!B268 -> Daily egg mass std. | N4: =Language!B269 -> Rearing | O4: =Language!B273 -> Cum. | P4: =Language!B271 -> Seconds farm | Q4: =Language!B272 -> Packing station | R4: =Language!B182 -> Weekly | S4: =Language!B274 -> Day hen | T4: =Language!B275 -> Cum. feed/bird /day | U4: =Language!B276 -> Wk FCR | V4: =Language!B277 -> Cum. FCR | W4: =Language!B278 -> Wk FCR/egg | X4: =Language!B279 -> Cum FCR/egg | Y4: =Language!B280 -> Cumulative egg number | Z4: =Language!B281 -> Std. | AD4: Semaine de présence cumulées | AF4: STD | AM4: STD
B5: Real | C5: Real | D5: Real | F5: Real | H5: Graph redone | K5: Daily | L5: Real | AE5: Wk | AF5: Lay 1 | AG5: Lay 2 | AH5: Lay 3 | AI5: Lay 4 | AJ5: Lay 5 | AK5: Lay 6 | AL5: Lay 7 | AM5: EW 1 | AN5: EW 2 | AO5: EW 3 | AP5: EW 4 | AQ5: EW 5 | AR5: EW 6 | AS5: EW 7 | AT5: eggs HD | AU5: eggs HD cum | AV5: Week | AW5: egg mass HD wk | AX5: egg mass HD cum | BA5: PMO RETENU | BC5: Cumul Petit | BD5: Cumul Moyen | BE5: Cumul Gros | BF5: Cumul Très gros
A6: 16 | B6: #N/A | C6: #N/A | D6: #N/A | E6: #N/A | F6: #N/A | G6: #N/A | H6: #N/A | I6: #N/A | J6: #N/A | K6: #N/A | L6: #N/A | M6: #N/A | O6: #N/A | P6: #N/A | Q6: #N/A | R6: #N/A | T6: #N/A | U6: #N/A | V6: #N/A | W6: #N/A | X6: #N/A | Y6: #N/A | Z6: #N/A | BA6: =IF('Egg grading'!C10="",IF('Egg grading'!B10="","",'Egg grading'!B10),'Egg grading'!C10) | BC6: ='Egg grading'!K10 | BD6: ='Egg grading'!L10 | BE6: ='Egg grading'!M10 | BF6: ='Egg grading'!N10
A7: ='Production data'!B14 -> 17 | B7: =IF('Production data'!C14="",#N/A,'Production data'!C14) -> #N/A | C7: =IF(OR('Input Laying'!E15=0),#N/A,'Input Laying'!E15/'Input Laying'!$G$6*100*25) -> #N/A | D7: =IF(OR('Production data'!D14="",'Production data'!D14=0),0,'Production data'!D14) -> 0 | E7: =IF(OR(Std!B20="",Std!B20=0),0,Std!B20) -> 0 | F7: =IF('Production data'!H14="",0,'Production data'!H14) -> 0 | G7: =IF(OR(Std!C20="",Std!C20=0),0,Std!C20) -> 0 | H7: =IF(I7<0,#N/A,I7) -> #N/A | I7: =('Input Laying'!AH15-1000)/25 -> -40 | J7: =IF((Std!D20-1000)/25<15,#N/A,(Std!D20-1000)/25) -> 17.58 | K7: =IF('Production data'!P14="",#N/A,'Production data'!P14) -> #N/A | L7: =IF('Production data'!L14="",#N/A,'Production data'!L14) -> #N/A | M7: =IF(Std!E20=0,0,Std!E20) -> 0 | O7: =IF('Input Laying'!V15=0,NA(),IF('Input Laying'!V15="",NA(),'Input Laying'!W15/'Input Laying'!O15*100)) -> #N/A | P7: =IF('Input Laying'!T15="",#N/A,'Input Laying'!T15/'Input Laying'!N15*100) -> #N/A | Q7: =IF('Input Laying'!U15="",#N/A,'Input Laying'!U15/'Input Laying'!N15*100) -> #N/A | R7: =IF('Input Laying'!V15="",#N/A,'Production data'!W14) | S7: ='Input Laying'!D15*7 -> 0 | T7: =IF(OR('Input Laying'!AF15="",'Input Laying'!D15=0,'Input Laying'!O15=0),"#N/A",'Input Laying'!AF15/'Input Laying'!D15/(AD7*7)*1000) -> #N/A | U7: =IF('Production data'!U14="",#N/A,'Production data'!U14) -> #N/A | V7: =IF('Production data'!V14="",#N/A,'Production data'!V14) -> #N/A | W7: =IF('Production data'!S14="",#N/A,'Production data'!S14) -> #N/A | X7: =IF('Production data'!T14="",#N/A,'Production data'!T14) -> #N/A | Y7: =IF('Input Laying'!E15="",#N/A,'Production data'!F14) -> #N/A | Z7: =IF('Production data'!G14="",#N/A,'Production data'!G14) -> #N/A | AD7: =IF('Input Laying'!AF15=0,0,(IF('Input Laying'!N15>0,1,IF('Input Laying'!O15>0,0,1)))) -> 0 | AM7: =G7 -> 0 | AT7: =E7*7/100 -> 0 | AU7: =AT7+AU6 -> 0 | AW7: =(G7*E7/100)*7 -> 0 | AX7: =AX6+(AW7/1000) -> 0 | AZ7: 17 | BA7: =IF('Egg grading'!C11="",IF('Egg grading'!B11="","",'Egg grading'!B11),'Egg grading'!C11) | BC7: =IF(BC6="",'Egg grading'!K11,BC6+'Egg grading'!K11) | BD7: =IF(BD6="",'Egg grading'!L11,BD6+'Egg grading'!L11) | BE7: =IF(BE6="",'Egg grading'!M11,BE6+'Egg grading'!M11) | BF7: =IF(BF6="",'Egg grading'!N11,BF6+'Egg grading'!N11)
A8: ='Production data'!B15 -> 18 | B8: =IF('Production data'!C15="",#N/A,'Production data'!C15) -> #N/A | C8: =IF(OR('Input Laying'!E16=0,'Input Laying'!D15=0),#N/A,'Input Laying'!E16/'Input Laying'!D15*100*25) -> #N/A | D8: =IF(OR('Production data'!D15="",'Production data'!D15=0),0,'Production data'!D15) -> 0 | E8: =IF(OR(Std!B21="",Std!B21=0),0,Std!B21) -> 3 | F8: =IF('Production data'!H15="",0,'Production data'!H15) -> 0 | G8: =IF(OR(Std!C21="",Std!C21=0),0,Std!C21) -> 42.49223 | H8: =IF(I8<0,#N/A,I8) -> #N/A | I8: =('Input Laying'!AH16-1000)/25 -> -40 | J8: =IF((Std!D21-1000)/25<15,#N/A,(Std!D21-1000)/25) -> 20 | K8: =IF('Production data'!P15="",#N/A,'Production data'!P15) -> #N/A | L8: =IF('Production data'!L15="",#N/A,'Production data'!L15) -> #N/A | M8: =IF(Std!E21=0,#N/A,Std!E21) -> 1.2747669 | O8: =IF('Input Laying'!V16=0,NA(),IF('Input Laying'!V16="",NA(),'Input Laying'!W16/'Input Laying'!O16*100)) -> #N/A | P8: =IF('Input Laying'!T16="",#N/A,'Input Laying'!T16/'Input Laying'!N16*100) -> #N/A | Q8: =IF('Input Laying'!U16="",#N/A,'Input Laying'!U16/'Input Laying'!N16*100) -> #N/A | R8: =IF('Input Laying'!V16="",#N/A,'Production data'!W15) | S8: ='Input Laying'!D16*7+'Graph values'!S7 -> 0 | T8: =IF(OR('Input Laying'!AF16="",'Input Laying'!D16=0,'Input Laying'!O16=0),"#N/A",'Input Laying'!AF16/'Input Laying'!D16/(AD8*7)*1000) -> #N/A | U8: =IF('Production data'!U15="",#N/A,'Production data'!U15) -> #N/A | V8: =IF('Production data'!V15="",#N/A,'Production data'!V15) -> #N/A | W8: =IF('Production data'!S15="",#N/A,'Production data'!S15) -> #N/A | X8: =IF('Production data'!T15="",#N/A,'Production data'!T15) -> #N/A | Y8: =IF('Input Laying'!E16="",#N/A,'Production data'!F15) -> #N/A | Z8: =IF('Production data'!G15="",#N/A,'Production data'!G15) -> 0.2097984 | AD8: =IF('Input Laying'!AF16=0,0,(IF('Input Laying'!N16>0,1,IF('Input Laying'!O16>0,0,1))))+AD7 -> 0 | AE8: 18 | AF8: =IF(E8<1,#N/A,E8) -> 3 | AG8: =AF8-1.5 -> 1.5 | AH8: =AG8-1.5 -> 0 | AI8: =AH8-1.5 -> -1.5 | AJ8: =AI8-1.5 -> -3 | AK8: =AJ8-1.5 -> -4.5 | AL8: =AK8-1.5 -> -6 | AM8: =G8 -> 42.49223 | AN8: =AM8-0.3 -> 42.19223 | AO8: =AN8-0.3 -> 41.89223 | AP8: =AO8-0.3 -> 41.59223 | AQ8: =AP8-0.3 -> 41.29223 | AR8: =AQ8-0.3 -> 40.99223 | AS8: =AR8-0.3 -> 40.69223 | AT8: =E8*7/100 -> 0.21 | AU8: =AT8+AU7 -> 0.21 | AV8: 18 | AW8: =(G8*E8/100)*7 -> 8.9233682 | AX8: =AX7+(AW8/1000) -> 0.0089233682 | AZ8: 18 | BA8: =IF('Egg grading'!C12="",IF('Egg grading'!B12="","",'Egg grading'!B12),'Egg grading'!C12) -> 42.49223 | BC8: =IF(BC7="",'Egg grading'!K12,BC7+'Egg grading'!K12) | BD8: =IF(BD7="",'Egg grading'!L12,BD7+'Egg grading'!L12) | BE8: =IF(BE7="",'Egg grading'!M12,BE7+'Egg grading'!M12) | BF8: =IF(BF7="",'Egg grading'!N12,BF7+'Egg grading'!N12)
A9: ='Production data'!B16 -> 19 | B9: =IF('Production data'!C16="",#N/A,'Production data'!C16) -> #N/A | C9: =IF(OR('Input Laying'!E17=0,'Input Laying'!D16=0),#N/A,'Input Laying'!E17/'Input Laying'!D16*100*25) -> #N/A | D9: =IF(OR('Production data'!D16="",'Production data'!D16=0),0,'Production data'!D16) -> 0 | E9: =IF(OR(Std!B22="",Std!B22=0),0,Std!B22) -> 10.981495 | F9: =IF('Production data'!H16="",0,'Production data'!H16) -> 0 | G9: =IF(OR(Std!C22="",Std!C22=0),#N/A,Std!C22) -> 46.165714 | H9: =IF(I9<0,#N/A,I9) -> #N/A | I9: =('Input Laying'!AH17-1000)/25 -> -40 | J9: =IF((Std!D22-1000)/25<15,#N/A,(Std!D22-1000)/25) -> 22.345926 | K9: =IF('Production data'!P16="",#N/A,'Production data'!P16) -> #N/A | L9: =IF('Production data'!L16="",#N/A,'Production data'!L16) -> #N/A | M9: =IF(Std!E22=0,#N/A,Std!E22) -> 5.0696855 | O9: =IF('Input Laying'!V17=0,NA(),IF('Input Laying'!V17="",NA(),'Input Laying'!W17/'Input Laying'!O17*100)) -> #N/A | P9: =IF('Input Laying'!T17="",#N/A,'Input Laying'!T17/'Input Laying'!N17*100) -> #N/A | Q9: =IF('Input Laying'!U17="",#N/A,'Input Laying'!U17/'Input Laying'!N17*100) -> #N/A | R9: =IF('Input Laying'!V17="",#N/A,'Production data'!W16) | S9: ='Input Laying'!D17*7+'Graph values'!S8 -> 0 | T9: =IF(OR('Input Laying'!AF17="",'Input Laying'!D17=0,'Input Laying'!O17=0),"#N/A",'Input Laying'!AF17/'Input Laying'!D17/(AD9*7)*1000) -> #N/A | U9: =IF('Production data'!U16="",#N/A,'Production data'!U16) -> #N/A | V9: =IF('Production data'!V16="",#N/A,'Production data'!V16) -> #N/A | W9: =IF('Production data'!S16="",#N/A,'Production data'!S16) -> #N/A | X9: =IF('Production data'!T16="",#N/A,'Production data'!T16) -> #N/A | Y9: =IF('Input Laying'!E17="",#N/A,'Production data'!F16) -> #N/A | Z9: =IF('Production data'!G16="",#N/A,'Production data'!G16) -> 0.97702713 | AD9: =IF('Input Laying'!AF17=0,0,(IF('Input Laying'!N17>0,1,IF('Input Laying'!O17>0,0,1))))+AD8 -> 0 | AE9: 19 | AF9: =IF(E9<1,#N/A,E9) -> 10.981495 | AG9: =IF(AF9-1.5<1,#N/A,AF9-1.5) -> 9.4814948 | AH9: =IF(AG9-1.5<1,#N/A,AG9-1.5) -> 7.9814948 | AI9: =IF(AH9-1.5<1,#N/A,AH9-1.5) -> 6.4814948 | AJ9: =IF(AI9-1.5<1,#N/A,AI9-1.5) -> 4.9814948 | AK9: =IF(AJ9-1.5<1,#N/A,AJ9-1.5) -> 3.4814948 | AL9: =IF(AK9-1.5<1,#N/A,AK9-1.5) -> 1.9814948 | AM9: =G9 -> 46.165714 | AN9: =AM9-0.3 -> 45.865714 | AO9: =AN9-0.3 -> 45.565714 | AP9: =AO9-0.3 -> 45.265714 | AQ9: =AP9-0.3 -> 44.965714 | AR9: =AQ9-0.3 -> 44.665714 | AS9: =AR9-0.3 -> 44.365714 | AT9: =E9*7/100 -> 0.76870464 | AU9: =AT9+AU8 -> 0.97870464 | AV9: 19 | AW9: =IFERROR((G9*E9/100)*7,0) -> 35.487798 | AX9: =AX8+(AW9/1000) -> 0.044411166 | AZ9: 19 | BA9: =IF('Egg grading'!C13="",IF('Egg grading'!B13="","",'Egg grading'!B13),'Egg grading'!C13) -> 46.165714 | BC9: =IF(BC8="",'Egg grading'!K13,BC8+'Egg grading'!K13) | BD9: =IF(BD8="",'Egg grading'!L13,BD8+'Egg grading'!L13) | BE9: =IF(BE8="",'Egg grading'!M13,BE8+'Egg grading'!M13) | BF9: =IF(BF8="",'Egg grading'!N13,BF8+'Egg grading'!N13)
A10: ='Production data'!B17 -> 20 | B10: =IF('Production data'!C17="",#N/A,'Production data'!C17) -> #N/A | C10: =IF(OR('Input Laying'!E18=0,'Input Laying'!D17=0),#N/A,'Input Laying'!E18/'Input Laying'!D17*100*25) -> #N/A | D10: =IF(OR('Production data'!D17="",'Production data'!D17=0),0,'Production data'!D17) -> 0 | E10: =IF(OR(Std!B23="",Std!B23=0),0,Std!B23) -> 31.090326 | F10: =IF('Production data'!H17="",#N/A,'Production data'!H17) -> #N/A | G10: =IF(OR(Std!C23="",Std!C23=0),#N/A,Std!C23) -> 49.278199 | H10: =IF(I10<0,#N/A,I10) -> #N/A | I10: =('Input Laying'!AH18-1000)/25 -> -40 | J10: =IF((Std!D23-1000)/25<15,#N/A,(Std!D23-1000)/25) -> 24.860649 | K10: =IF('Production data'!P17="",#N/A,'Production data'!P17) -> #N/A | L10: =IF('Production data'!L17="",#N/A,'Production data'!L17) -> #N/A | M10: =IF(Std!E23=0,#N/A,Std!E23) -> 15.320753 | O10: =IF('Input Laying'!V18=0,NA(),IF('Input Laying'!V18="",NA(),'Input Laying'!W18/'Input Laying'!O18*100)) -> #N/A | P10: =IF('Input Laying'!T18="",#N/A,'Input Laying'!T18/'Input Laying'!N18*100) -> #N/A | Q10: =IF('Input Laying'!U18="",#N/A,'Input Laying'!U18/'Input Laying'!N18*100) -> #N/A | R10: =IF('Input Laying'!V18="",#N/A,'Production data'!W17) | S10: ='Input Laying'!D18*7+'Graph values'!S9 -> 0 | T10: =IF(OR('Input Laying'!AF18="",'Input Laying'!D18=0,'Input Laying'!O18=0),"#N/A",'Input Laying'!AF18/'Input Laying'!D18/(AD10*7)*1000) -> #N/A | U10: =IF('Production data'!U17="",#N/A,'Production data'!U17) -> #N/A | V10: =IF('Production data'!V17="",#N/A,'Production data'!V17) -> #N/A | W10: =IF('Production data'!S17="",#N/A,'Production data'!S17) -> #N/A | X10: =IF('Production data'!T17="",#N/A,'Production data'!T17) -> #N/A | Y10: =IF('Input Laying'!E18="",#N/A,'Production data'!F17) -> #N/A | Z10: =IF('Production data'!G17="",#N/A,'Production data'!G17) -> 3.1470821 | AD10: =IF('Input Laying'!AF18=0,0,(IF('Input Laying'!N18>0,1,IF('Input Laying'!O18>0,0,1))))+AD9 -> 0 | AE10: 20 | AF10: =IF(E10<10,#N/A,E10) -> 31.090326 | AG10: =IF(AF10-1.5<10,#N/A,AF10-1.5) -> 29.590326 | AH10: =IF(AG10-1.5<10,#N/A,AG10-1.5) -> 28.090326 | AI10: =IF(AH10-1.5<10,#N/A,AH10-1.5) -> 26.590326 | AJ10: =IF(AI10-1.5<10,#N/A,AI10-1.5) -> 25.090326 | AK10: =IF(AJ10-1.5<10,#N/A,AJ10-1.5) -> 23.590326 | AL10: =IF(AK10-1.5<10,#N/A,AK10-1.5) -> 22.090326 | AM10: =G10 -> 49.278199 | AN10: =AM10-0.3 -> 48.978199 | AO10: =AN10-0.3 -> 48.678199 | AP10: =AO10-0.3 -> 48.378199 | AQ10: =AP10-0.3 -> 48.078199 | AR10: =AQ10-0.3 -> 47.778199 | AS10: =AR10-0.3 -> 47.478199 | AT10: =E10*7/100 -> 2.1763228 | AU10: =AT10+AU9 -> 3.1550274 | AV10: 20 | AW10: =(G10*E10/100)*7 -> 107.24527 | AX10: =AX9+(AW10/1000) -> 0.15165643 | AZ10: 20 | BA10: =IF('Egg grading'!C14="",IF('Egg grading'!B14="","",'Egg grading'!B14),'Egg grading'!C14) -> 49.278199 | BC10: =IF(BC9="",'Egg grading'!K14,BC9+'Egg grading'!K14) | BD10: =IF(BD9="",'Egg grading'!L14,BD9+'Egg grading'!L14) | BE10: =IF(BE9="",'Egg grading'!M14,BE9+'Egg grading'!M14) | BF10: =IF(BF9="",'Egg grading'!N14,BF9+'Egg grading'!N14)
A11: ='Production data'!B18 -> 21 | B11: =IF('Production data'!C18="",#N/A,'Production data'!C18) -> #N/A | C11: =IF(OR('Input Laying'!E19=0,'Input Laying'!D18=0),#N/A,'Input Laying'!E19/'Input Laying'!D18*100*25) -> #N/A | D11: =IF(OR('Production data'!D18="",'Production data'!D18=0),0,'Production data'!D18) -> 0 | E11: =IF(OR(Std!B24="",Std!B24=0),0,Std!B24) -> 49.193548 | F11: =IF('Production data'!H18="",#N/A,'Production data'!H18) -> #N/A | G11: =IF(OR(Std!C24="",Std!C24=0),#N/A,Std!C24) -> 51.89266 | H11: =IF(I11<0,#N/A,I11) -> #N/A | I11: =('Input Laying'!AH19-1000)/25 -> -40 | J11: =IF((Std!D24-1000)/25<15,#N/A,(Std!D24-1000)/25) -> 27.375372 | K11: =IF('Production data'!P18="",#N/A,'Production data'!P18) -> #N/A | L11: =IF('Production data'!L18="",#N/A,'Production data'!L18) -> #N/A | M11: =IF(Std!E24=0,#N/A,Std!E24) -> 25.527841 | O11: =IF('Input Laying'!V19=0,NA(),IF('Input Laying'!V19="",NA(),'Input Laying'!W19/'Input Laying'!O19*100)) -> #N/A | P11: =IF('Input Laying'!T19="",#N/A,'Input Laying'!T19/'Input Laying'!N19*100) -> #N/A | Q11: =IF('Input Laying'!U19="",#N/A,'Input Laying'!U19/'Input Laying'!N19*100) -> #N/A | R11: =IF('Input Laying'!V19="",#N/A,'Production data'!W18) | S11: ='Input Laying'!D19*7+'Graph values'!S10 -> 0 | T11: =IF(OR('Input Laying'!AF19="",'Input Laying'!D19=0,'Input Laying'!O19=0),"#N/A",'Input Laying'!AF19/'Input Laying'!D19/(AD11*7)*1000) -> #N/A | U11: =IF('Production data'!U18="",#N/A,'Production data'!U18) -> #N/A | V11: =IF('Production data'!V18="",#N/A,'Production data'!V18) -> #N/A | W11: =IF('Production data'!S18="",#N/A,'Production data'!S18) -> #N/A | X11: =IF('Production data'!T18="",#N/A,'Production data'!T18) -> #N/A | Y11: =IF('Input Laying'!E19="",#N/A,'Production data'!F18) -> #N/A | Z11: =IF('Production data'!G18="",#N/A,'Production data'!G18) -> 6.5774073 | AD11: =IF('Input Laying'!AF19=0,0,(IF('Input Laying'!N19>0,1,IF('Input Laying'!O19>0,0,1))))+AD10 -> 0 | AE11: 21 | AF11: =IF(E11<10,#N/A,E11) -> 49.193548 | AG11: =AF11-1.5 -> 47.693548 | AH11: =AG11-1.5 -> 46.193548 | AI11: =AH11-1.5 -> 44.693548 | AJ11: =AI11-1.5 -> 43.193548 | AK11: =AJ11-1.5 -> 41.693548 | AL11: =AK11-1.5 -> 40.193548 | AM11: =G11 -> 51.89266 | AN11: =AM11-0.3 -> 51.59266 | AO11: =AN11-0.3 -> 51.29266 | AP11: =AO11-0.3 -> 50.99266 | AQ11: =AP11-0.3 -> 50.69266 | AR11: =AQ11-0.3 -> 50.39266 | AS11: =AR11-0.3 -> 50.09266 | AT11: =E11*7/100 -> 3.4435484 | AU11: =AT11+AU10 -> 6.5985758 | AV11: 21 | AW11: =(G11*E11/100)*7 -> 178.69489 | AX11: =AX10+(AW11/1000) -> 0.33035132 | AZ11: 21 | BA11: =IF('Egg grading'!C15="",IF('Egg grading'!B15="","",'Egg grading'!B15),'Egg grading'!C15) -> 51.89266 | BC11: =IF(BC10="",'Egg grading'!K15,BC10+'Egg grading'!K15) | BD11: =IF(BD10="",'Egg grading'!L15,BD10+'Egg grading'!L15) | BE11: =IF(BE10="",'Egg grading'!M15,BE10+'Egg grading'!M15) | BF11: =IF(BF10="",'Egg grading'!N15,BF10+'Egg grading'!N15)
A12: ='Production data'!B19 -> 22 | B12: =IF('Production data'!C19="",#N/A,'Production data'!C19) -> #N/A | C12: =IF(OR('Input Laying'!E20=0,'Input Laying'!D19=0),#N/A,'Input Laying'!E20/'Input Laying'!D19*100*25) -> #N/A | D12: =IF(OR('Production data'!D19="",'Production data'!D19=0),0,'Production data'!D19) -> 0 | E12: =IF(OR(Std!B25="",Std!B25=0),0,Std!B25) -> 66.812852 | F12: =IF('Production data'!H19="",#N/A,'Production data'!H19) -> #N/A | G12: =IF(OR(Std!C25="",Std!C25=0),#N/A,Std!C25) -> 54.068332 | H12: =IF(I12<0,#N/A,I12) -> #N/A | I12: =('Input Laying'!AH20-1000)/25 -> -40 | J12: =IF((Std!D25-1000)/25<15,#N/A,(Std!D25-1000)/25) -> 28.913523 | K12: =IF('Production data'!P19="",#N/A,'Production data'!P19) -> #N/A | L12: =IF('Production data'!L19="",#N/A,'Production data'!L19) -> #N/A | M12: =IF(Std!E25=0,#N/A,Std!E25) -> 36.124595 | O12: =IF('Input Laying'!V20=0,NA(),IF('Input Laying'!V20="",NA(),'Input Laying'!W20/'Input Laying'!O20*100)) -> #N/A | P12: =IF('Input Laying'!T20="",#N/A,'Input Laying'!T20/'Input Laying'!N20*100) -> #N/A | Q12: =IF('Input Laying'!U20="",#N/A,'Input Laying'!U20/'Input Laying'!N20*100) -> #N/A | R12: =IF('Input Laying'!V20="",#N/A,'Production data'!W19) | S12: ='Input Laying'!D20*7+'Graph values'!S11 -> 0 | T12: =IF(OR('Input Laying'!AF20="",'Input Laying'!D20=0,'Input Laying'!O20=0),"#N/A",'Input Laying'!AF20/'Input Laying'!D20/(AD12*7)*1000) -> #N/A | U12: =IF('Production data'!U19="",#N/A,'Production data'!U19) -> #N/A | V12: =IF('Production data'!V19="",#N/A,'Production data'!V19) -> #N/A | W12: =IF('Production data'!S19="",#N/A,'Production data'!S19) -> #N/A | X12: =IF('Production data'!T19="",#N/A,'Production data'!T19) -> #N/A | Y12: =IF('Input Laying'!E20="",#N/A,'Production data'!F19) -> #N/A | Z12: =IF('Production data'!G19="",#N/A,'Production data'!G19) -> 11.231858 | AD12: =IF('Input Laying'!AF20=0,0,(IF('Input Laying'!N20>0,1,IF('Input Laying'!O20>0,0,1))))+AD11 -> 0 | AE12: 22 | AF12: =IF(E12<10,#N/A,E12) -> 66.812852 | AG12: =AF12-1.5 -> 65.312852 | AH12: =AG12-1.5 -> 63.812852 | AI12: =AH12-1.5 -> 62.312852 | AJ12: =AI12-1.5 -> 60.812852 | AK12: =AJ12-1.5 -> 59.312852 | AL12: =AK12-1.5 -> 57.812852 | AM12: =G12 -> 54.068332 | AN12: =AM12-0.3 -> 53.768332 | AO12: =AN12-0.3 -> 53.468332 | AP12: =AO12-0.3 -> 53.168332 | AQ12: =AP12-0.3 -> 52.868332 | AR12: =AQ12-0.3 -> 52.568332 | AS12: =AR12-0.3 -> 52.268332 | AT12: =E12*7/100 -> 4.6768996 | AU12: =AT12+AU11 -> 11.275475 | AV12: 22 | AW12: =(G12*E12/100)*7 -> 252.87216 | AX12: =AX11+(AW12/1000) -> 0.58322348 | AZ12: 22 | BA12: =IF('Egg grading'!C16="",IF('Egg grading'!B16="","",'Egg grading'!B16),'Egg grading'!C16) -> 54.068332 | BC12: =IF(BC11="",'Egg grading'!K16,BC11+'Egg grading'!K16) | BD12: =IF(BD11="",'Egg grading'!L16,BD11+'Egg grading'!L16) | BE12: =IF(BE11="",'Egg grading'!M16,BE11+'Egg grading'!M16) | BF12: =IF(BF11="",'Egg grading'!N16,BF11+'Egg grading'!N16)
A13: ='Production data'!B20 -> 23 | B13: =IF('Production data'!C20="",#N/A,'Production data'!C20) -> #N/A | C13: =IF(OR('Input Laying'!E21=0,'Input Laying'!D20=0),#N/A,'Input Laying'!E21/'Input Laying'!D20*100*25) -> #N/A | D13: =IF(OR('Production data'!D20="",'Production data'!D20=0),0,'Production data'!D20) -> 0 | E13: =IF(OR(Std!B26="",Std!B26=0),0,Std!B26) -> 82.197174 | F13: =IF('Production data'!H20="",#N/A,'Production data'!H20) -> #N/A | G13: =IF(OR(Std!C26="",Std!C26=0),#N/A,Std!C26) -> 55.860707 | H13: =IF(I13<0,#N/A,I13) -> #N/A | I13: =('Input Laying'!AH21-1000)/25 -> -40 | J13: =IF((Std!D26-1000)/25<15,#N/A,(Std!D26-1000)/25) -> 30.013506 | K13: =IF('Production data'!P20="",#N/A,'Production data'!P20) -> #N/A | L13: =IF('Production data'!L20="",#N/A,'Production data'!L20) -> #N/A | M13: =IF(Std!E26=0,#N/A,Std!E26) -> 45.915922 | O13: =IF('Input Laying'!V21=0,NA(),IF('Input Laying'!V21="",NA(),'Input Laying'!W21/'Input Laying'!O21*100)) -> #N/A | P13: =IF('Input Laying'!T21="",#N/A,'Input Laying'!T21/'Input Laying'!N21*100) -> #N/A | Q13: =IF('Input Laying'!U21="",#N/A,'Input Laying'!U21/'Input Laying'!N21*100) -> #N/A | R13: =IF('Input Laying'!V21="",#N/A,'Production data'!W20) | S13: ='Input Laying'!D21*7+'Graph values'!S12 -> 0 | T13: =IF(OR('Input Laying'!AF21="",'Input Laying'!D21=0,'Input Laying'!O21=0),"#N/A",'Input Laying'!AF21/'Input Laying'!D21/(AD13*7)*1000) -> #N/A | U13: =IF('Production data'!U20="",#N/A,'Production data'!U20) -> #N/A | V13: =IF('Production data'!V20="",#N/A,'Production data'!V20) -> #N/A | W13: =IF('Production data'!S20="",#N/A,'Production data'!S20) -> #N/A | X13: =IF('Production data'!T20="",#N/A,'Production data'!T20) -> #N/A | Y13: =IF('Input Laying'!E21="",#N/A,'Production data'!F20) -> #N/A | Z13: =IF('Production data'!G20="",#N/A,'Production data'!G20) -> 16.952518 | AD13: =IF('Input Laying'!AF21=0,0,(IF('Input Laying'!N21>0,1,IF('Input Laying'!O21>0,0,1))))+AD12 -> 0 | AE13: 23 | AF13: =IF(E13<10,#N/A,E13) -> 82.197174 | AG13: =AF13-0.9 -> 81.297174 | AH13: =AG13-0.9 -> 80.397174 | AI13: =AH13-1.5 -> 78.897174 | AJ13: =AI13-0.9 -> 77.997174 | AK13: =AJ13-0.9 -> 77.097174 | AL13: =AK13-0.9 -> 76.197174 | AM13: =G13 -> 55.860707 | AN13: =AM13-0.3 -> 55.560707 | AO13: =AN13-0.3 -> 55.260707 | AP13: =AO13-0.3 -> 54.960707 | AQ13: =AP13-0.3 -> 54.660707 | AR13: =AQ13-0.3 -> 54.360707 | AS13: =AR13-0.3 -> 54.060707 | AT13: =E13*7/100 -> 5.7538022 | AU13: =AT13+AU12 -> 17.029278 | AV13: 23 | AW13: =(G13*E13/100)*7 -> 321.41146 | AX13: =AX12+(AW13/1000) -> 0.90463494 | AZ13: 23 | BA13: =IF('Egg grading'!C17="",IF('Egg grading'!B17="","",'Egg grading'!B17),'Egg grading'!C17) -> 55.860707 | BC13: =IF(BC12="",'Egg grading'!K17,BC12+'Egg grading'!K17) | BD13: =IF(BD12="",'Egg grading'!L17,BD12+'Egg grading'!L17) | BE13: =IF(BE12="",'Egg grading'!M17,BE12+'Egg grading'!M17) | BF13: =IF(BF12="",'Egg grading'!N17,BF12+'Egg grading'!N17)
A14: ='Production data'!B21 -> 24 | B14: =IF('Production data'!C21="",#N/A,'Production data'!C21) -> #N/A | C14: =IF(OR('Input Laying'!E22=0,'Input Laying'!D21=0),#N/A,'Input Laying'!E22/'Input Laying'!D21*100*25) -> #N/A | D14: =IF(OR('Production data'!D21="",'Production data'!D21=0),0,'Production data'!D21) -> 0 | E14: =IF(OR(Std!B27="",Std!B27=0),0,Std!B27) -> 90.322705 | F14: =IF('Production data'!H21="",#N/A,'Production data'!H21) -> #N/A | G14: =IF(OR(Std!C27="",Std!C27=0),#N/A,Std!C27) -> 57.321534 | H14: =IF(I14<0,#N/A,I14) -> #N/A | I14: =('Input Laying'!AH22-1000)/25 -> -40 | J14: =IF((Std!D27-1000)/25<15,#N/A,(Std!D27-1000)/25) -> 30.777683 | K14: =IF('Production data'!P21="",#N/A,'Production data'!P21) -> #N/A | L14: =IF('Production data'!L21="",#N/A,'Production data'!L21) -> #N/A | M14: =IF(Std!E27=0,#N/A,Std!E27) -> 51.77436 | O14: =IF('Input Laying'!V22=0,NA(),IF('Input Laying'!V22="",NA(),'Input Laying'!W22/'Input Laying'!O22*100)) -> #N/A | P14: =IF('Input Laying'!T22="",#N/A,'Input Laying'!T22/'Input Laying'!N22*100) -> #N/A | Q14: =IF('Input Laying'!U22="",#N/A,'Input Laying'!U22/'Input Laying'!N22*100) -> #N/A | R14: =IF('Input Laying'!V22="",#N/A,'Production data'!W21) | S14: ='Input Laying'!D22*7+'Graph values'!S13 -> 0 | T14: =IF(OR('Input Laying'!AF22="",'Input Laying'!D22=0,'Input Laying'!O22=0),"#N/A",'Input Laying'!AF22/'Input Laying'!D22/(AD14*7)*1000) -> #N/A | U14: =IF('Production data'!U21="",#N/A,'Production data'!U21) -> #N/A | V14: =IF('Production data'!V21="",#N/A,'Production data'!V21) -> #N/A | W14: =IF('Production data'!S21="",#N/A,'Production data'!S21) -> #N/A | X14: =IF('Production data'!T21="",#N/A,'Production data'!T21) -> #N/A | Y14: =IF('Input Laying'!E22="",#N/A,'Production data'!F21) -> #N/A | Z14: =IF('Production data'!G21="",#N/A,'Production data'!G21) -> 23.23262 | AD14: =IF('Input Laying'!AF22=0,0,(IF('Input Laying'!N22>0,1,IF('Input Laying'!O22>0,0,1))))+AD13 -> 0 | AE14: 24 | AF14: =IF(E14<10,#N/A,E14) -> 90.322705 | AG14: =AF14-0.45 -> 89.872705 | AH14: =AG14-0.45 -> 89.422705 | AI14: =AH14-1.5 -> 87.922705 | AJ14: =AI14-0.45 -> 87.472705 | AK14: =AJ14-0.45 -> 87.022705 | AL14: =AK14-0.45 -> 86.572705 | AM14: =G14 -> 57.321534 | AN14: =AM14-0.3 -> 57.021534 | AO14: =AN14-0.3 -> 56.721534 | AP14: =AO14-0.3 -> 56.421534 | AQ14: =AP14-0.3 -> 56.121534 | AR14: =AQ14-0.3 -> 55.821534 | AS14: =AR14-0.3 -> 55.521534 | AT14: =E14*7/100 -> 6.3225894 | AU14: =AT14+AU13 -> 23.351867 | AV14: 24 | AW14: =(G14*E14/100)*7 -> 362.42052 | AX14: =AX13+(AW14/1000) -> 1.2670555 | AZ14: 24 | BA14: =IF('Egg grading'!C18="",IF('Egg grading'!B18="","",'Egg grading'!B18),'Egg grading'!C18) -> 57.321534 | BC14: =IF(BC13="",'Egg grading'!K18,BC13+'Egg grading'!K18) | BD14: =IF(BD13="",'Egg grading'!L18,BD13+'Egg grading'!L18) | BE14: =IF(BE13="",'Egg grading'!M18,BE13+'Egg grading'!M18) | BF14: =IF(BF13="",'Egg grading'!N18,BF13+'Egg grading'!N18)
A15: ='Production data'!B22 -> 25 | B15: =IF('Production data'!C22="",#N/A,'Production data'!C22) -> #N/A | C15: =IF(OR('Input Laying'!E23=0,'Input Laying'!D22=0),#N/A,'Input Laying'!E23/'Input Laying'!D22*100*25) -> #N/A | D15: =IF(OR('Production data'!D22="",'Production data'!D22=0),0,'Production data'!D22) -> 0 | E15: =IF(OR(Std!B28="",Std!B28=0),0,Std!B28) -> 92.969804 | F15: =IF('Production data'!H22="",#N/A,'Production data'!H22) -> #N/A | G15: =IF(OR(Std!C28="",Std!C28=0),#N/A,Std!C28) -> 58.498823 | H15: =IF(I15<0,#N/A,I15) -> #N/A | I15: =('Input Laying'!AH23-1000)/25 -> -40 | J15: =IF((Std!D28-1000)/25<15,#N/A,(Std!D28-1000)/25) -> 31.296531 | K15: =IF('Production data'!P22="",#N/A,'Production data'!P22) -> #N/A | L15: =IF('Production data'!L22="",#N/A,'Production data'!L22) -> #N/A | M15: =IF(Std!E28=0,#N/A,Std!E28) -> 54.386241 | O15: =IF('Input Laying'!V23=0,NA(),IF('Input Laying'!V23="",NA(),'Input Laying'!W23/'Input Laying'!O23*100)) -> #N/A | P15: =IF('Input Laying'!T23="",#N/A,'Input Laying'!T23/'Input Laying'!N23*100) -> #N/A | Q15: =IF('Input Laying'!U23="",#N/A,'Input Laying'!U23/'Input Laying'!N23*100) -> #N/A | R15: =IF('Input Laying'!V23="",#N/A,'Production data'!W22) | S15: ='Input Laying'!D23*7+'Graph values'!S14 -> 0 | T15: =IF(OR('Input Laying'!AF23="",'Input Laying'!D23=0,'Input Laying'!O23=0),"#N/A",'Input Laying'!AF23/'Input Laying'!D23/(AD15*7)*1000) -> #N/A | U15: =IF('Production data'!U22="",#N/A,'Production data'!U22) -> #N/A | V15: =IF('Production data'!V22="",#N/A,'Production data'!V22) -> #N/A | W15: =IF('Production data'!S22="",#N/A,'Production data'!S22) -> #N/A | X15: =IF('Production data'!T22="",#N/A,'Production data'!T22) -> #N/A | Y15: =IF('Input Laying'!E23="",#N/A,'Production data'!F22) -> #N/A | Z15: =IF('Production data'!G22="",#N/A,'Production data'!G22) -> 29.690525 | AD15: =IF('Input Laying'!AF23=0,0,(IF('Input Laying'!N23>0,1,IF('Input Laying'!O23>0,0,1))))+AD14 -> 0 | AE15: 25 | AF15: =IF(E15<10,#N/A,E15) -> 92.969804 | AG15: =AF15-0.45 -> 92.519804 | AH15: =AG15-0.45 -> 92.069804 | AI15: =AH15-1.5 -> 90.569804 | AJ15: =AI15-0.45 -> 90.119804 | AK15: =AJ15-0.45 -> 89.669804 | AL15: =AK15-0.45 -> 89.219804 | AM15: =G15 -> 58.498823 | AN15: =AM15-0.3 -> 58.198823 | AO15: =AN15-0.3 -> 57.898823 | AP15: =AO15-0.3 -> 57.598823 | AQ15: =AP15-0.3 -> 57.298823 | AR15: =AQ15-0.3 -> 56.998823 | AS15: =AR15-0.3 -> 56.698823 | AT15: =E15*7/100 -> 6.5078863 | AU15: =AT15+AU14 -> 29.859753 | AV15: 25 | AW15: =(G15*E15/100)*7 -> 380.70368 | AX15: =AX14+(AW15/1000) -> 1.6477591 | AZ15: 25 | BA15: =IF('Egg grading'!C19="",IF('Egg grading'!B19="","",'Egg grading'!B19),'Egg grading'!C19) -> 58.498823 | BC15: =IF(BC14="",'Egg grading'!K19,BC14+'Egg grading'!K19) | BD15: =IF(BD14="",'Egg grading'!L19,BD14+'Egg grading'!L19) | BE15: =IF(BE14="",'Egg grading'!M19,BE14+'Egg grading'!M19) | BF15: =IF(BF14="",'Egg grading'!N19,BF14+'Egg grading'!N19)
A16: ='Production data'!B23 -> 26 | B16: =IF('Production data'!C23="",#N/A,'Production data'!C23) -> #N/A | C16: =IF(OR('Input Laying'!E24=0,'Input Laying'!D23=0),#N/A,'Input Laying'!E24/'Input Laying'!D23*100*25) -> #N/A | D16: =IF(OR('Production data'!D23="",'Production data'!D23=0),0,'Production data'!D23) -> 0 | E16: =IF(OR(Std!B29="",Std!B29=0),0,Std!B29) -> 94.027254 | F16: =IF('Production data'!H23="",#N/A,'Production data'!H23) -> #N/A | G16: =IF(OR(Std!C29="",Std!C29=0),#N/A,Std!C29) -> 59.436839 | H16: =IF(I16<0,#N/A,I16) -> #N/A | I16: =('Input Laying'!AH24-1000)/25 -> -40 | J16: =IF((Std!D29-1000)/25<15,#N/A,(Std!D29-1000)/25) -> 31.648644 | K16: =IF('Production data'!P23="",#N/A,'Production data'!P23) -> #N/A | L16: =IF('Production data'!L23="",#N/A,'Production data'!L23) -> #N/A | M16: =IF(Std!E29=0,#N/A,Std!E29) -> 55.886828 | O16: =IF('Input Laying'!V24=0,NA(),IF('Input Laying'!V24="",NA(),'Input Laying'!W24/'Input Laying'!O24*100)) -> #N/A | P16: =IF('Input Laying'!T24="",#N/A,'Input Laying'!T24/'Input Laying'!N24*100) -> #N/A | Q16: =IF('Input Laying'!U24="",#N/A,'Input Laying'!U24/'Input Laying'!N24*100) -> #N/A | R16: =IF('Input Laying'!V24="",#N/A,'Production data'!W23) | S16: ='Input Laying'!D24*7+'Graph values'!S15 -> 0 | T16: =IF(OR('Input Laying'!AF24="",'Input Laying'!D24=0,'Input Laying'!O24=0),"#N/A",'Input Laying'!AF24/'Input Laying'!D24/(AD16*7)*1000) -> #N/A | U16: =IF('Production data'!U23="",#N/A,'Production data'!U23) -> #N/A | V16: =IF('Production data'!V23="",#N/A,'Production data'!V23) -> #N/A | W16: =IF('Production data'!S23="",#N/A,'Production data'!S23) -> #N/A | X16: =IF('Production data'!T23="",#N/A,'Production data'!T23) -> #N/A | Y16: =IF('Input Laying'!E24="",#N/A,'Production data'!F23) -> #N/A | Z16: =IF('Production data'!G23="",#N/A,'Production data'!G23) -> 36.215565 | AD16: =IF('Input Laying'!AF24=0,0,(IF('Input Laying'!N24>0,1,IF('Input Laying'!O24>0,0,1))))+AD15 -> 0 | AE16: 26 | AF16: =IF(E16<10,#N/A,E16) -> 94.027254 | AG16: =AF16-0.45 -> 93.577254 | AH16: =AG16-0.45 -> 93.127254 | AI16: =AH16-1.5 -> 91.627254 | AJ16: =AI16-0.45 -> 91.177254 | AK16: =AJ16-0.45 -> 90.727254 | AL16: =AK16-0.45 -> 90.277254 | AM16: =G16 -> 59.436839 | AN16: =AM16-0.3 -> 59.136839 | AO16: =AN16-0.3 -> 58.836839 | AP16: =AO16-0.3 -> 58.536839 | AQ16: =AP16-0.3 -> 58.236839 | AR16: =AQ16-0.3 -> 57.936839 | AS16: =AR16-0.3 -> 57.636839 | AT16: =E16*7/100 -> 6.5819078 | AU16: =AT16+AU15 -> 36.441661 | AV16: 26 | AW16: =(G16*E16/100)*7 -> 391.20779 | AX16: =AX15+(AW16/1000) -> 2.0389669 | AZ16: 26 | BA16: =IF('Egg grading'!C20="",IF('Egg grading'!B20="","",'Egg grading'!B20),'Egg grading'!C20) -> 59.436839 | BC16: =IF(BC15="",'Egg grading'!K20,BC15+'Egg grading'!K20) | BD16: =IF(BD15="",'Egg grading'!L20,BD15+'Egg grading'!L20) | BE16: =IF(BE15="",'Egg grading'!M20,BE15+'Egg grading'!M20) | BF16: =IF(BF15="",'Egg grading'!N20,BF15+'Egg grading'!N20)
A17: ='Production data'!B24 -> 27 | B17: =IF('Production data'!C24="",#N/A,'Production data'!C24) -> #N/A | C17: =IF(OR('Input Laying'!E25=0,'Input Laying'!D24=0),#N/A,'Input Laying'!E25/'Input Laying'!D24*100*25) -> #N/A | D17: =IF(OR('Production data'!D24="",'Production data'!D24=0),0,'Production data'!D24) -> 0 | E17: =IF(OR(Std!B30="",Std!B30=0),0,Std!B30) -> 94.815695 | F17: =IF('Production data'!H24="",#N/A,'Production data'!H24) -> #N/A | G17: =IF(OR(Std!C30="",Std!C30=0),#N/A,Std!C30) -> 60.176109 | H17: =IF(I17<0,#N/A,I17) -> #N/A | I17: =('Input Laying'!AH25-1000)/25 -> -40 | J17: =IF((Std!D30-1000)/25<15,#N/A,(Std!D30-1000)/25) -> 31.900726 | K17: =IF('Production data'!P24="",#N/A,'Production data'!P24) -> #N/A | L17: =IF('Production data'!L24="",#N/A,'Production data'!L24) -> #N/A | M17: =IF(Std!E30=0,#N/A,Std!E30) -> 57.056396 | O17: =IF('Input Laying'!V25=0,NA(),IF('Input Laying'!V25="",NA(),'Input Laying'!W25/'Input Laying'!O25*100)) -> #N/A | P17: =IF('Input Laying'!T25="",#N/A,'Input Laying'!T25/'Input Laying'!N25*100) -> #N/A | Q17: =IF('Input Laying'!U25="",#N/A,'Input Laying'!U25/'Input Laying'!N25*100) -> #N/A | R17: =IF('Input Laying'!V25="",#N/A,'Production data'!W24) | S17: ='Input Laying'!D25*7+'Graph values'!S16 -> 0 | T17: =IF(OR('Input Laying'!AF25="",'Input Laying'!D25=0,'Input Laying'!O25=0),"#N/A",'Input Laying'!AF25/'Input Laying'!D25/(AD17*7)*1000) -> #N/A | U17: =IF('Production data'!U24="",#N/A,'Production data'!U24) -> #N/A | V17: =IF('Production data'!V24="",#N/A,'Production data'!V24) -> #N/A | W17: =IF('Production data'!S24="",#N/A,'Production data'!S24) -> #N/A | X17: =IF('Production data'!T24="",#N/A,'Production data'!T24) -> #N/A | Y17: =IF('Input Laying'!E25="",#N/A,'Production data'!F24) -> #N/A | Z17: =IF('Production data'!G24="",#N/A,'Production data'!G24) -> 42.788948 | AD17: =IF('Input Laying'!AF25=0,0,(IF('Input Laying'!N25>0,1,IF('Input Laying'!O25>0,0,1))))+AD16 -> 0 | AE17: 27 | AF17: =IF(E17<10,#N/A,E17) -> 94.815695 | AG17: =AF17-0.45 -> 94.365695 | AH17: =AG17-0.45 -> 93.915695 | AI17: =AH17-1.5 -> 92.415695 | AJ17: =AI17-0.45 -> 91.965695 | AK17: =AJ17-0.45 -> 91.515695 | AL17: =AK17-0.45 -> 91.065695 | AM17: =G17 -> 60.176109 | AN17: =AM17-0.3 -> 59.876109 | AO17: =AN17-0.3 -> 59.576109 | AP17: =AO17-0.3 -> 59.276109 | AQ17: =AP17-0.3 -> 58.976109 | AR17: =AQ17-0.3 -> 58.676109 | AS17: =AR17-0.3 -> 58.376109 | AT17: =E17*7/100 -> 6.6370987 | AU17: =AT17+AU16 -> 43.07876 | AV17: 27 | AW17: =(G17*E17/100)*7 -> 399.39477 | AX17: =AX16+(AW17/1000) -> 2.4383617 | AZ17: 27 | BA17: =IF('Egg grading'!C21="",IF('Egg grading'!B21="","",'Egg grading'!B21),'Egg grading'!C21) -> 60.176109 | BC17: =IF(BC16="",'Egg grading'!K21,BC16+'Egg grading'!K21) | BD17: =IF(BD16="",'Egg grading'!L21,BD16+'Egg grading'!L21) | BE17: =IF(BE16="",'Egg grading'!M21,BE16+'Egg grading'!M21) | BF17: =IF(BF16="",'Egg grading'!N21,BF16+'Egg grading'!N21)
